<?xml version="1.0" encoding="UTF-8"?><testsuite name="nosetests" tests="9" errors="9" failures="0" skip="0"><testcase classname="nose.failure.Failure" name="runTest" time="0.000"><error type="builtins.ModuleNotFoundError" message="No module named 'Bruch'"><![CDATA[Traceback (most recent call last):
  File "/usr/lib/python3.6/unittest/case.py", line 59, in testPartExecutor
    yield
  File "/usr/lib/python3.6/unittest/case.py", line 605, in run
    testMethod()
  File "/usr/lib/python3.6/site-packages/nose/failure.py", line 39, in runTest
    raise self.exc_val.with_traceback(self.tb)
  File "/usr/lib/python3.6/site-packages/nose/loader.py", line 417, in loadTestsFromName
    addr.filename, addr.module)
  File "/usr/lib/python3.6/site-packages/nose/importer.py", line 47, in importFromPath
    return self.importFromDir(dir_path, fqname)
  File "/usr/lib/python3.6/site-packages/nose/importer.py", line 94, in importFromDir
    mod = load_module(part_fqname, fh, filename, desc)
  File "/usr/lib/python3.6/imp.py", line 235, in load_module
    return load_source(name, filename, file)
  File "/usr/lib/python3.6/imp.py", line 172, in load_source
    module = _load(spec)
  File "<frozen importlib._bootstrap>", line 684, in _load
  File "<frozen importlib._bootstrap>", line 665, in _load_unlocked
  File "<frozen importlib._bootstrap_external>", line 678, in exec_module
  File "<frozen importlib._bootstrap>", line 219, in _call_with_frames_removed
  File "/home/mmueller/Documents/Schule/_5BHIT/A_SEW/A_04/bruch/test/Unit_Addition.py", line 7, in <module>
    from Bruch import *
ModuleNotFoundError: No module named 'Bruch'
]]></error></testcase><testcase classname="nose.failure.Failure" name="runTest" time="0.000"><error type="builtins.ModuleNotFoundError" message="No module named 'Bruch'"><![CDATA[Traceback (most recent call last):
  File "/usr/lib/python3.6/unittest/case.py", line 59, in testPartExecutor
    yield
  File "/usr/lib/python3.6/unittest/case.py", line 605, in run
    testMethod()
  File "/usr/lib/python3.6/site-packages/nose/failure.py", line 39, in runTest
    raise self.exc_val.with_traceback(self.tb)
  File "/usr/lib/python3.6/site-packages/nose/loader.py", line 417, in loadTestsFromName
    addr.filename, addr.module)
  File "/usr/lib/python3.6/site-packages/nose/importer.py", line 47, in importFromPath
    return self.importFromDir(dir_path, fqname)
  File "/usr/lib/python3.6/site-packages/nose/importer.py", line 94, in importFromDir
    mod = load_module(part_fqname, fh, filename, desc)
  File "/usr/lib/python3.6/imp.py", line 235, in load_module
    return load_source(name, filename, file)
  File "/usr/lib/python3.6/imp.py", line 172, in load_source
    module = _load(spec)
  File "<frozen importlib._bootstrap>", line 684, in _load
  File "<frozen importlib._bootstrap>", line 665, in _load_unlocked
  File "<frozen importlib._bootstrap_external>", line 678, in exec_module
  File "<frozen importlib._bootstrap>", line 219, in _call_with_frames_removed
  File "/home/mmueller/Documents/Schule/_5BHIT/A_SEW/A_04/bruch/test/Unit_Allgemein.py", line 7, in <module>
    from Bruch import *
ModuleNotFoundError: No module named 'Bruch'
]]></error></testcase><testcase classname="nose.failure.Failure" name="runTest" time="0.000"><error type="builtins.ModuleNotFoundError" message="No module named 'Bruch'"><![CDATA[Traceback (most recent call last):
  File "/usr/lib/python3.6/unittest/case.py", line 59, in testPartExecutor
    yield
  File "/usr/lib/python3.6/unittest/case.py", line 605, in run
    testMethod()
  File "/usr/lib/python3.6/site-packages/nose/failure.py", line 39, in runTest
    raise self.exc_val.with_traceback(self.tb)
  File "/usr/lib/python3.6/site-packages/nose/loader.py", line 417, in loadTestsFromName
    addr.filename, addr.module)
  File "/usr/lib/python3.6/site-packages/nose/importer.py", line 47, in importFromPath
    return self.importFromDir(dir_path, fqname)
  File "/usr/lib/python3.6/site-packages/nose/importer.py", line 94, in importFromDir
    mod = load_module(part_fqname, fh, filename, desc)
  File "/usr/lib/python3.6/imp.py", line 235, in load_module
    return load_source(name, filename, file)
  File "/usr/lib/python3.6/imp.py", line 172, in load_source
    module = _load(spec)
  File "<frozen importlib._bootstrap>", line 684, in _load
  File "<frozen importlib._bootstrap>", line 665, in _load_unlocked
  File "<frozen importlib._bootstrap_external>", line 678, in exec_module
  File "<frozen importlib._bootstrap>", line 219, in _call_with_frames_removed
  File "/home/mmueller/Documents/Schule/_5BHIT/A_SEW/A_04/bruch/test/Unit_Division.py", line 7, in <module>
    from Bruch import *
ModuleNotFoundError: No module named 'Bruch'
]]></error></testcase><testcase classname="nose.failure.Failure" name="runTest" time="0.000"><error type="builtins.ModuleNotFoundError" message="No module named 'Bruch'"><![CDATA[Traceback (most recent call last):
  File "/usr/lib/python3.6/unittest/case.py", line 59, in testPartExecutor
    yield
  File "/usr/lib/python3.6/unittest/case.py", line 605, in run
    testMethod()
  File "/usr/lib/python3.6/site-packages/nose/failure.py", line 39, in runTest
    raise self.exc_val.with_traceback(self.tb)
  File "/usr/lib/python3.6/site-packages/nose/loader.py", line 417, in loadTestsFromName
    addr.filename, addr.module)
  File "/usr/lib/python3.6/site-packages/nose/importer.py", line 47, in importFromPath
    return self.importFromDir(dir_path, fqname)
  File "/usr/lib/python3.6/site-packages/nose/importer.py", line 94, in importFromDir
    mod = load_module(part_fqname, fh, filename, desc)
  File "/usr/lib/python3.6/imp.py", line 235, in load_module
    return load_source(name, filename, file)
  File "/usr/lib/python3.6/imp.py", line 172, in load_source
    module = _load(spec)
  File "<frozen importlib._bootstrap>", line 684, in _load
  File "<frozen importlib._bootstrap>", line 665, in _load_unlocked
  File "<frozen importlib._bootstrap_external>", line 678, in exec_module
  File "<frozen importlib._bootstrap>", line 219, in _call_with_frames_removed
  File "/home/mmueller/Documents/Schule/_5BHIT/A_SEW/A_04/bruch/test/Unit_Multiplikation.py", line 7, in <module>
    from Bruch import *
ModuleNotFoundError: No module named 'Bruch'
]]></error></testcase><testcase classname="nose.failure.Failure" name="runTest" time="0.000"><error type="builtins.ModuleNotFoundError" message="No module named 'Bruch'"><![CDATA[Traceback (most recent call last):
  File "/usr/lib/python3.6/unittest/case.py", line 59, in testPartExecutor
    yield
  File "/usr/lib/python3.6/unittest/case.py", line 605, in run
    testMethod()
  File "/usr/lib/python3.6/site-packages/nose/failure.py", line 39, in runTest
    raise self.exc_val.with_traceback(self.tb)
  File "/usr/lib/python3.6/site-packages/nose/loader.py", line 417, in loadTestsFromName
    addr.filename, addr.module)
  File "/usr/lib/python3.6/site-packages/nose/importer.py", line 47, in importFromPath
    return self.importFromDir(dir_path, fqname)
  File "/usr/lib/python3.6/site-packages/nose/importer.py", line 94, in importFromDir
    mod = load_module(part_fqname, fh, filename, desc)
  File "/usr/lib/python3.6/imp.py", line 235, in load_module
    return load_source(name, filename, file)
  File "/usr/lib/python3.6/imp.py", line 172, in load_source
    module = _load(spec)
  File "<frozen importlib._bootstrap>", line 684, in _load
  File "<frozen importlib._bootstrap>", line 665, in _load_unlocked
  File "<frozen importlib._bootstrap_external>", line 678, in exec_module
  File "<frozen importlib._bootstrap>", line 219, in _call_with_frames_removed
  File "/home/mmueller/Documents/Schule/_5BHIT/A_SEW/A_04/bruch/test/Unit_String.py", line 7, in <module>
    from Bruch import *
ModuleNotFoundError: No module named 'Bruch'
]]></error></testcase><testcase classname="nose.failure.Failure" name="runTest" time="0.000"><error type="builtins.ModuleNotFoundError" message="No module named 'Bruch'"><![CDATA[Traceback (most recent call last):
  File "/usr/lib/python3.6/unittest/case.py", line 59, in testPartExecutor
    yield
  File "/usr/lib/python3.6/unittest/case.py", line 605, in run
    testMethod()
  File "/usr/lib/python3.6/site-packages/nose/failure.py", line 39, in runTest
    raise self.exc_val.with_traceback(self.tb)
  File "/usr/lib/python3.6/site-packages/nose/loader.py", line 417, in loadTestsFromName
    addr.filename, addr.module)
  File "/usr/lib/python3.6/site-packages/nose/importer.py", line 47, in importFromPath
    return self.importFromDir(dir_path, fqname)
  File "/usr/lib/python3.6/site-packages/nose/importer.py", line 94, in importFromDir
    mod = load_module(part_fqname, fh, filename, desc)
  File "/usr/lib/python3.6/imp.py", line 235, in load_module
    return load_source(name, filename, file)
  File "/usr/lib/python3.6/imp.py", line 172, in load_source
    module = _load(spec)
  File "<frozen importlib._bootstrap>", line 684, in _load
  File "<frozen importlib._bootstrap>", line 665, in _load_unlocked
  File "<frozen importlib._bootstrap_external>", line 678, in exec_module
  File "<frozen importlib._bootstrap>", line 219, in _call_with_frames_removed
  File "/home/mmueller/Documents/Schule/_5BHIT/A_SEW/A_04/bruch/test/Unit_Subtraktion.py", line 7, in <module>
    from Bruch import *
ModuleNotFoundError: No module named 'Bruch'
]]></error></testcase><testcase classname="nose.failure.Failure" name="runTest" time="0.000"><error type="builtins.ModuleNotFoundError" message="No module named 'Bruch'"><![CDATA[Traceback (most recent call last):
  File "/usr/lib/python3.6/unittest/case.py", line 59, in testPartExecutor
    yield
  File "/usr/lib/python3.6/unittest/case.py", line 605, in run
    testMethod()
  File "/usr/lib/python3.6/site-packages/nose/failure.py", line 39, in runTest
    raise self.exc_val.with_traceback(self.tb)
  File "/usr/lib/python3.6/site-packages/nose/loader.py", line 417, in loadTestsFromName
    addr.filename, addr.module)
  File "/usr/lib/python3.6/site-packages/nose/importer.py", line 47, in importFromPath
    return self.importFromDir(dir_path, fqname)
  File "/usr/lib/python3.6/site-packages/nose/importer.py", line 94, in importFromDir
    mod = load_module(part_fqname, fh, filename, desc)
  File "/usr/lib/python3.6/imp.py", line 235, in load_module
    return load_source(name, filename, file)
  File "/usr/lib/python3.6/imp.py", line 172, in load_source
    module = _load(spec)
  File "<frozen importlib._bootstrap>", line 684, in _load
  File "<frozen importlib._bootstrap>", line 665, in _load_unlocked
  File "<frozen importlib._bootstrap_external>", line 678, in exec_module
  File "<frozen importlib._bootstrap>", line 219, in _call_with_frames_removed
  File "/home/mmueller/Documents/Schule/_5BHIT/A_SEW/A_04/bruch/test/Unit_Vergleich.py", line 7, in <module>
    from Bruch import *
ModuleNotFoundError: No module named 'Bruch'
]]></error></testcase><testcase classname="nose.failure.Failure" name="runTest" time="0.000"><error type="builtins.ModuleNotFoundError" message="No module named 'Bruch'"><![CDATA[Traceback (most recent call last):
  File "/usr/lib/python3.6/unittest/case.py", line 59, in testPartExecutor
    yield
  File "/usr/lib/python3.6/unittest/case.py", line 605, in run
    testMethod()
  File "/usr/lib/python3.6/site-packages/nose/failure.py", line 39, in runTest
    raise self.exc_val.with_traceback(self.tb)
  File "/usr/lib/python3.6/site-packages/nose/loader.py", line 417, in loadTestsFromName
    addr.filename, addr.module)
  File "/usr/lib/python3.6/site-packages/nose/importer.py", line 47, in importFromPath
    return self.importFromDir(dir_path, fqname)
  File "/usr/lib/python3.6/site-packages/nose/importer.py", line 94, in importFromDir
    mod = load_module(part_fqname, fh, filename, desc)
  File "/usr/lib/python3.6/imp.py", line 235, in load_module
    return load_source(name, filename, file)
  File "/usr/lib/python3.6/imp.py", line 172, in load_source
    module = _load(spec)
  File "<frozen importlib._bootstrap>", line 684, in _load
  File "<frozen importlib._bootstrap>", line 665, in _load_unlocked
  File "<frozen importlib._bootstrap_external>", line 678, in exec_module
  File "<frozen importlib._bootstrap>", line 219, in _call_with_frames_removed
  File "/home/mmueller/Documents/Schule/_5BHIT/A_SEW/A_04/bruch/test/Unit_Zusatz.py", line 6, in <module>
    from Bruch import *
ModuleNotFoundError: No module named 'Bruch'
]]></error></testcase><testcase classname="nose.failure.Failure" name="runTest" time="0.000"><error type="builtins.ModuleNotFoundError" message="No module named 'Bruch'"><![CDATA[Traceback (most recent call last):
  File "/usr/lib/python3.6/unittest/case.py", line 59, in testPartExecutor
    yield
  File "/usr/lib/python3.6/unittest/case.py", line 605, in run
    testMethod()
  File "/usr/lib/python3.6/site-packages/nose/failure.py", line 39, in runTest
    raise self.exc_val.with_traceback(self.tb)
  File "/usr/lib/python3.6/site-packages/nose/loader.py", line 417, in loadTestsFromName
    addr.filename, addr.module)
  File "/usr/lib/python3.6/site-packages/nose/importer.py", line 47, in importFromPath
    return self.importFromDir(dir_path, fqname)
  File "/usr/lib/python3.6/site-packages/nose/importer.py", line 94, in importFromDir
    mod = load_module(part_fqname, fh, filename, desc)
  File "/usr/lib/python3.6/imp.py", line 235, in load_module
    return load_source(name, filename, file)
  File "/usr/lib/python3.6/imp.py", line 172, in load_source
    module = _load(spec)
  File "<frozen importlib._bootstrap>", line 684, in _load
  File "<frozen importlib._bootstrap>", line 665, in _load_unlocked
  File "<frozen importlib._bootstrap_external>", line 678, in exec_module
  File "<frozen importlib._bootstrap>", line 219, in _call_with_frames_removed
  File "/home/mmueller/Documents/Schule/_5BHIT/A_SEW/A_04/bruch/test/testfall.py", line 7, in <module>
    from Bruch import *
ModuleNotFoundError: No module named 'Bruch'
]]></error></testcase></testsuite>